<sdf version='1.6'>
  <world name='empty_underwater'>
    <physics name='default_physics' default='1' type='ode'>
      <max_step_size>0.002</max_step_size>
      <real_time_factor>1</real_time_factor>
      <real_time_update_rate>500</real_time_update_rate>
      <ode>
        <solver>
          <type>quick</type>
          <iters>50</iters>
          <sor>0.5</sor>
          <use_dynamic_moi_rescaling>0</use_dynamic_moi_rescaling>
        </solver>
        <constraints>
          <cfm>0</cfm>
          <erp>0.2</erp>
          <contact_max_correcting_vel>100</contact_max_correcting_vel>
          <contact_surface_layer>0.001</contact_surface_layer>
        </constraints>
      </ode>
    </physics>
    <scene>
      <ambient>0.01 0.01 0.01 1</ambient>
      <sky>
        <clouds>
          <speed>12</speed>
        </clouds>
      </sky>
      <shadows>1</shadows>
      <fog>
        <color>0.1 0.2 0.3 1</color>
        <type>linear</type>
        <density>0.001</density>
        <start>10</start>
        <end>200</end>
      </fog>
      <background>0.7 0.7 0.7 1</background>
    </scene>
    <spherical_coordinates>
      <latitude_deg>56.719</latitude_deg>
      <longitude_deg>3.51562</longitude_deg>
      <surface_model>EARTH_WGS84</surface_model>
      <elevation>0</elevation>
      <heading_deg>0</heading_deg>
    </spherical_coordinates>
    <light name='sun' type='directional'>
      <cast_shadows>1</cast_shadows>
      <pose frame=''>0 0 10 0 -0 0</pose>
      <diffuse>0.8 0.8 0.8 1</diffuse>
      <specular>0.1 0.1 0.1 1</specular>
      <attenuation>
        <range>1000</range>
        <constant>0.9</constant>
        <linear>0.01</linear>
        <quadratic>0.001</quadratic>
      </attenuation>
      <direction>-0.5 0.5 -1</direction>
    </light>
    <model name='ocean_box'>
      <static>1</static>
      <link name='link'>
        <visual name='ground'>
          <cast_shadows>0</cast_shadows>
          <pose frame=''>0 0 -100 0 -0 0</pose>
          <geometry>
            <box>
              <size>2000 2000 0.1</size>
            </box>
          </geometry>
          <material>
            <script>
              <uri>file://Media/materials/scripts/sand.material</uri>
              <name>UUVSimulator/SandAndStones</name>
            </script>
          </material>
        </visual>
        <collision name='ground'>
          <pose frame=''>0 0 -100 0 -0 0</pose>
          <geometry>
            <box>
              <size>2000 2000 0.1</size>
            </box>
          </geometry>
          <max_contacts>10</max_contacts>
          <surface>
            <contact>
              <ode/>
            </contact>
            <bounce/>
            <friction>
              <torsional>
                <ode/>
              </torsional>
              <ode/>
            </friction>
          </surface>
        </collision>
        <visual name='surface'>
          <cast_shadows>0</cast_shadows>
          <pose frame=''>0 0 0 0 -0 0</pose>
          <geometry>
            <box>
              <size>2000 2000 0.1</size>
            </box>
          </geometry>
          <material>
            <script>
              <uri>file://Media/materials/scripts/water.material</uri>
              <name>UUVSimulator/StaticDeepWater</name>
            </script>
          </material>
        </visual>
        <visual name='north'>
          <cast_shadows>0</cast_shadows>
          <pose frame=''>1000 0 -50 0 -0 0</pose>
          <geometry>
            <box>
              <size>0.1 2000 100</size>
            </box>
          </geometry>
          <material>
            <script>
              <uri>file://Media/materials/scripts/water.material</uri>
              <name>UUVSimulator/SeaWall</name>
            </script>
          </material>
        </visual>
        <visual name='south'>
          <cast_shadows>0</cast_shadows>
          <pose frame=''>-1000 0 -50 0 -0 0</pose>
          <geometry>
            <box>
              <size>0.1 2000 100</size>
            </box>
          </geometry>
          <material>
            <script>
              <uri>file://Media/materials/scripts/water.material</uri>
              <name>UUVSimulator/SeaWall</name>
            </script>
          </material>
        </visual>
        <visual name='east'>
          <cast_shadows>0</cast_shadows>
          <pose frame=''>0 -1000 -50 0 -0 0</pose>
          <geometry>
            <box>
              <size>2000 0.1 100</size>
            </box>
          </geometry>
          <material>
            <script>
              <uri>file://Media/materials/scripts/water.material</uri>
              <name>UUVSimulator/SeaWall</name>
            </script>
          </material>
        </visual>
        <visual name='west'>
          <cast_shadows>0</cast_shadows>
          <pose frame=''>0 1000 -50 0 -0 0</pose>
          <geometry>
            <box>
              <size>2000 0.1 100</size>
            </box>
          </geometry>
          <material>
            <script>
              <uri>file://Media/materials/scripts/water.material</uri>
              <name>UUVSimulator/SeaWall</name>
            </script>
          </material>
        </visual>
        <self_collide>0</self_collide>
        <kinematic>0</kinematic>
        <gravity>1</gravity>
      </link>
      <pose frame=''>0 0 0 0 -0 0</pose>
    </model>
    <plugin name='underwater_current_plugin' filename='libuuv_underwater_current_ros_plugin.so'>
      <namespace>hydrodynamics</namespace>
      <constant_current>
        <topic>current_velocity</topic>
        <velocity>
          <mean>0</mean>
          <min>0</min>
          <max>5</max>
          <mu>0.0</mu>
          <noiseAmp>0.0</noiseAmp>
        </velocity>
        <horizontal_angle>
          <mean>0</mean>
          <min>-3.141592653589793238</min>
          <max>3.141592653589793238</max>
          <mu>0.0</mu>
          <noiseAmp>0.0</noiseAmp>
        </horizontal_angle>
        <vertical_angle>
          <mean>0</mean>
          <min>-3.141592653589793238</min>
          <max>3.141592653589793238</max>
          <mu>0.0</mu>
          <noiseAmp>0.0</noiseAmp>
        </vertical_angle>
      </constant_current>
    </plugin>
    <plugin name='sc_interface' filename='libuuv_sc_ros_interface_plugin.so'/>
    <gravity>0 0 -9.8</gravity>
    <magnetic_field>6e-06 2.3e-05 -4.2e-05</magnetic_field>
    <atmosphere type='adiabatic'/>
    <model name='aquadrone'>
      <link name='base_link'>
        <pose frame=''>0 0 0 0 -0 0</pose>
        <inertial>
          <pose frame=''>9e-06 0 3e-06 0 -0 0</pose>
          <mass>57.3036</mass>
          <inertia>
            <ixx>100</ixx>
            <ixy>0</ixy>
            <ixz>-9.99983e-05</ixz>
            <iyy>100</iyy>
            <iyz>0</iyz>
            <izz>1.00025</izz>
          </inertia>
        </inertial>
        <collision name='base_link_collision'>
          <pose frame=''>0 0 0 0 -0 0</pose>
          <geometry>
            <box>
              <size>0.9144 0.3048 0.2</size>
            </box>
          </geometry>
          <surface>
            <contact>
              <ode/>
            </contact>
            <friction>
              <ode/>
              <torsional>
                <ode/>
              </torsional>
            </friction>
            <bounce/>
          </surface>
          <max_contacts>10</max_contacts>
        </collision>
        <visual name='base_link_visual'>
          <pose frame=''>0 0 0 0 -0 0</pose>
          <geometry>
            <box>
              <size>0.9144 0.3048 0.2</size>
            </box>
          </geometry>
          <material>
            <script>
              <uri>__default__</uri>
              <name>__default__</name>
            </script>
          </material>
        </visual>
        <visual name='base_link_visual_1'>
          <pose frame=''>0.4572 0 0 0 -0 0</pose>
          <geometry>
            <sphere>
              <radius>0.1524</radius>
            </sphere>
          </geometry>
          <material>
            <script>
              <uri>__default__</uri>
              <name>__default__</name>
            </script>
          </material>
        </visual>
        <visual name='base_link_fixed_joint_lump__camera_front_cam_link_visual_2'>
          <pose frame=''>0.525 0 0.2 0 -0 0</pose>
          <geometry>
            <box>
              <size>0.1 0.05 0.05</size>
            </box>
          </geometry>
          <material>
            <script>
              <uri>__default__</uri>
              <name>__default__</name>
            </script>
          </material>
        </visual>
        <velocity_decay/>
        <gravity>1</gravity>
        <velocity_decay/>
        <self_collide>0</self_collide>
        <sensor name='front_cam' type='camera'>
          <update_rate>10</update_rate>
          <camera name='front_cam'>
            <horizontal_fov>1.39626</horizontal_fov>
            <image>
              <width>640</width>
              <height>480</height>
              <format>R8G8B8</format>
            </image>
            <clip>
              <near>0.02</near>
              <far>300</far>
            </clip>
            <noise>
              <type>gaussian</type>
              <mean>0</mean>
              <stddev>0.007</stddev>
            </noise>
          </camera>
          <plugin name='camera_controller' filename='libgazebo_ros_camera.so'>
            <alwaysOn>true</alwaysOn>
            <updateRate>0.0</updateRate>
            <cameraName>aquadrone/out/front_cam</cameraName>
            <imageTopicName>image_raw</imageTopicName>
            <cameraInfoTopicName>camera_info</cameraInfoTopicName>
            <frameName>camera_link</frameName>
            <hackBaseline>0.07</hackBaseline>
            <distortionK1>0.0</distortionK1>
            <distortionK2>0.0</distortionK2>
            <distortionK3>0.0</distortionK3>
            <distortionT1>0.0</distortionT1>
            <distortionT2>0.0</distortionT2>
            <robotNamespace>/</robotNamespace>
          </plugin>
          <pose frame=''>0.5 0 0.2 0 -0 0</pose>
        </sensor>
        <kinematic>0</kinematic>
      </link>
      <link name='aquadrone/out//imu_link'>
        <pose frame=''>0 0 0 0 -0 0</pose>
        <inertial>
          <pose frame=''>0 0 0 0 -0 0</pose>
          <mass>0.015</mass>
          <inertia>
            <ixx>1e-05</ixx>
            <ixy>0</ixy>
            <ixz>0</ixz>
            <iyy>1e-05</iyy>
            <iyz>0</iyz>
            <izz>1e-05</izz>
          </inertia>
        </inertial>
        <self_collide>0</self_collide>
        <kinematic>0</kinematic>
        <gravity>1</gravity>
      </link>
      <joint name='aquadrone/out//imu_joint' type='revolute'>
        <child>aquadrone/out//imu_link</child>
        <parent>base_link</parent>
        <axis>
          <xyz>1 0 0</xyz>
          <limit>
            <lower>0</lower>
            <upper>0</upper>
            <effort>0</effort>
            <velocity>0</velocity>
          </limit>
          <dynamics>
            <spring_reference>0</spring_reference>
            <spring_stiffness>0</spring_stiffness>
          </dynamics>
          <use_parent_model_frame>1</use_parent_model_frame>
        </axis>
      </joint>
      <link name='aquadrone/out//pressure_link'>
        <pose frame=''>0 0 0 0 -0 0</pose>
        <inertial>
          <pose frame=''>0 0 0 0 -0 0</pose>
          <mass>0.015</mass>
          <inertia>
            <ixx>1e-05</ixx>
            <ixy>0</ixy>
            <ixz>0</ixz>
            <iyy>1e-05</iyy>
            <iyz>0</iyz>
            <izz>1e-05</izz>
          </inertia>
        </inertial>
        <collision name='aquadrone/out//pressure_link_collision'>
          <pose frame=''>0 0 0 3.14159 1.57079 3.14159</pose>
          <geometry>
            <cylinder>
              <length>1e-06</length>
              <radius>1e-06</radius>
            </cylinder>
          </geometry>
          <max_contacts>10</max_contacts>
          <surface>
            <contact>
              <ode/>
            </contact>
            <bounce/>
            <friction>
              <torsional>
                <ode/>
              </torsional>
              <ode/>
            </friction>
          </surface>
        </collision>
        <visual name='aquadrone/out//pressure_link_visual'>
          <pose frame=''>0 0 0 0 -0 0</pose>
          <geometry>
            <mesh>
              <scale>1 1 1</scale>
              <uri>file:///opt/ros/kinetic/share/uuv_sensor_ros_plugins/meshes/pressure.dae</uri>
            </mesh>
          </geometry>
        </visual>
        <self_collide>0</self_collide>
        <kinematic>0</kinematic>
        <gravity>1</gravity>
      </link>
      <joint name='aquadrone/out//pressure_joint' type='revolute'>
        <child>aquadrone/out//pressure_link</child>
        <parent>base_link</parent>
        <axis>
          <xyz>1 0 0</xyz>
          <limit>
            <lower>0</lower>
            <upper>0</upper>
            <effort>0</effort>
            <velocity>0</velocity>
          </limit>
          <dynamics>
            <spring_reference>0</spring_reference>
            <spring_stiffness>0</spring_stiffness>
          </dynamics>
          <use_parent_model_frame>1</use_parent_model_frame>
        </axis>
      </joint>
      <link name='thruster_0'>
        <pose frame=''>0.4 0.4 -0.2 3.14159 1.57079 3.14159</pose>
        <inertial>
          <pose frame=''>0 0 0 0 -0 0</pose>
          <mass>0.001</mass>
          <inertia>
            <ixx>1.7e-08</ixx>
            <ixy>0</ixy>
            <ixz>0</ixz>
            <iyy>1.7e-08</iyy>
            <iyz>0</iyz>
            <izz>1.7e-08</izz>
          </inertia>
        </inertial>
        <visual name='thruster_0_visual'>
          <pose frame=''>0.025 0 0 0 -0 0</pose>
          <geometry>
            <box>
              <size>0.01 0.01 0.1</size>
            </box>
          </geometry>
          <material>
            <script>
              <uri>__default__</uri>
              <name>__default__</name>
            </script>
          </material>
        </visual>
        <visual name='thruster_0_visual_1'>
          <pose frame=''>0 0 0 3.14159 1.57079 3.14159</pose>
          <geometry>
            <cylinder>
              <length>0.05</length>
              <radius>0.01</radius>
            </cylinder>
          </geometry>
          <material>
            <script>
              <uri>__default__</uri>
              <name>__default__</name>
            </script>
          </material>
        </visual>
        <gravity>1</gravity>
        <velocity_decay/>
        <self_collide>0</self_collide>
        <kinematic>0</kinematic>
      </link>
      <joint name='thruster_0_joint' type='revolute'>
        <child>thruster_0</child>
        <parent>base_link</parent>
        <axis>
          <xyz>0 0 -1</xyz>
          <limit>
            <lower>-1e+16</lower>
            <upper>1e+16</upper>
          </limit>
          <dynamics>
            <spring_reference>0</spring_reference>
            <spring_stiffness>0</spring_stiffness>
          </dynamics>
          <use_parent_model_frame>1</use_parent_model_frame>
        </axis>
      </joint>
      <link name='thruster_1'>
        <pose frame=''>0.4 -0.4 -0.2 3.14159 1.57079 3.14159</pose>
        <inertial>
          <pose frame=''>0 0 0 0 -0 0</pose>
          <mass>0.001</mass>
          <inertia>
            <ixx>1.7e-08</ixx>
            <ixy>0</ixy>
            <ixz>0</ixz>
            <iyy>1.7e-08</iyy>
            <iyz>0</iyz>
            <izz>1.7e-08</izz>
          </inertia>
        </inertial>
        <visual name='thruster_1_visual'>
          <pose frame=''>0.025 0 0 0 -0 0</pose>
          <geometry>
            <box>
              <size>0.01 0.01 0.1</size>
            </box>
          </geometry>
          <material>
            <script>
              <uri>__default__</uri>
              <name>__default__</name>
            </script>
          </material>
        </visual>
        <visual name='thruster_1_visual_1'>
          <pose frame=''>0 0 0 3.14159 1.57079 3.14159</pose>
          <geometry>
            <cylinder>
              <length>0.05</length>
              <radius>0.01</radius>
            </cylinder>
          </geometry>
          <material>
            <script>
              <uri>__default__</uri>
              <name>__default__</name>
            </script>
          </material>
        </visual>
        <gravity>1</gravity>
        <velocity_decay/>
        <self_collide>0</self_collide>
        <kinematic>0</kinematic>
      </link>
      <joint name='thruster_1_joint' type='revolute'>
        <child>thruster_1</child>
        <parent>base_link</parent>
        <axis>
          <xyz>0 0 -1</xyz>
          <limit>
            <lower>-1e+16</lower>
            <upper>1e+16</upper>
          </limit>
          <dynamics>
            <spring_reference>0</spring_reference>
            <spring_stiffness>0</spring_stiffness>
          </dynamics>
          <use_parent_model_frame>1</use_parent_model_frame>
        </axis>
      </joint>
      <link name='thruster_2'>
        <pose frame=''>-0.4 0.4 -0.2 3.14159 1.57079 3.14159</pose>
        <inertial>
          <pose frame=''>0 0 0 0 -0 0</pose>
          <mass>0.001</mass>
          <inertia>
            <ixx>1.7e-08</ixx>
            <ixy>0</ixy>
            <ixz>0</ixz>
            <iyy>1.7e-08</iyy>
            <iyz>0</iyz>
            <izz>1.7e-08</izz>
          </inertia>
        </inertial>
        <visual name='thruster_2_visual'>
          <pose frame=''>0.025 0 0 0 -0 0</pose>
          <geometry>
            <box>
              <size>0.01 0.01 0.1</size>
            </box>
          </geometry>
          <material>
            <script>
              <uri>__default__</uri>
              <name>__default__</name>
            </script>
          </material>
        </visual>
        <visual name='thruster_2_visual_1'>
          <pose frame=''>0 0 0 3.14159 1.57079 3.14159</pose>
          <geometry>
            <cylinder>
              <length>0.05</length>
              <radius>0.01</radius>
            </cylinder>
          </geometry>
          <material>
            <script>
              <uri>__default__</uri>
              <name>__default__</name>
            </script>
          </material>
        </visual>
        <gravity>1</gravity>
        <velocity_decay/>
        <self_collide>0</self_collide>
        <kinematic>0</kinematic>
      </link>
      <joint name='thruster_2_joint' type='revolute'>
        <child>thruster_2</child>
        <parent>base_link</parent>
        <axis>
          <xyz>0 0 -1</xyz>
          <limit>
            <lower>-1e+16</lower>
            <upper>1e+16</upper>
          </limit>
          <dynamics>
            <spring_reference>0</spring_reference>
            <spring_stiffness>0</spring_stiffness>
          </dynamics>
          <use_parent_model_frame>1</use_parent_model_frame>
        </axis>
      </joint>
      <link name='thruster_3'>
        <pose frame=''>-0.4 -0.4 -0.2 3.14159 1.57079 3.14159</pose>
        <inertial>
          <pose frame=''>0 0 0 0 -0 0</pose>
          <mass>0.001</mass>
          <inertia>
            <ixx>1.7e-08</ixx>
            <ixy>0</ixy>
            <ixz>0</ixz>
            <iyy>1.7e-08</iyy>
            <iyz>0</iyz>
            <izz>1.7e-08</izz>
          </inertia>
        </inertial>
        <visual name='thruster_3_visual'>
          <pose frame=''>0.025 0 0 0 -0 0</pose>
          <geometry>
            <box>
              <size>0.01 0.01 0.1</size>
            </box>
          </geometry>
          <material>
            <script>
              <uri>__default__</uri>
              <name>__default__</name>
            </script>
          </material>
        </visual>
        <visual name='thruster_3_visual_1'>
          <pose frame=''>0 0 0 3.14159 1.57079 3.14159</pose>
          <geometry>
            <cylinder>
              <length>0.05</length>
              <radius>0.01</radius>
            </cylinder>
          </geometry>
          <material>
            <script>
              <uri>__default__</uri>
              <name>__default__</name>
            </script>
          </material>
        </visual>
        <gravity>1</gravity>
        <velocity_decay/>
        <self_collide>0</self_collide>
        <kinematic>0</kinematic>
      </link>
      <joint name='thruster_3_joint' type='revolute'>
        <child>thruster_3</child>
        <parent>base_link</parent>
        <axis>
          <xyz>0 0 -1</xyz>
          <limit>
            <lower>-1e+16</lower>
            <upper>1e+16</upper>
          </limit>
          <dynamics>
            <spring_reference>0</spring_reference>
            <spring_stiffness>0</spring_stiffness>
          </dynamics>
          <use_parent_model_frame>1</use_parent_model_frame>
        </axis>
      </joint>
      <link name='thruster_4'>
        <pose frame=''>0 0.4 0 0 -0 0</pose>
        <inertial>
          <pose frame=''>0 0 0 0 -0 0</pose>
          <mass>0.001</mass>
          <inertia>
            <ixx>1.7e-08</ixx>
            <ixy>0</ixy>
            <ixz>0</ixz>
            <iyy>1.7e-08</iyy>
            <iyz>0</iyz>
            <izz>1.7e-08</izz>
          </inertia>
        </inertial>
        <visual name='thruster_4_visual'>
          <pose frame=''>0.025 0 0 0 -0 0</pose>
          <geometry>
            <box>
              <size>0.01 0.01 0.1</size>
            </box>
          </geometry>
          <material>
            <script>
              <uri>__default__</uri>
              <name>__default__</name>
            </script>
          </material>
        </visual>
        <visual name='thruster_4_visual_1'>
          <pose frame=''>0 0 0 3.14159 1.57079 3.14159</pose>
          <geometry>
            <cylinder>
              <length>0.05</length>
              <radius>0.01</radius>
            </cylinder>
          </geometry>
          <material>
            <script>
              <uri>__default__</uri>
              <name>__default__</name>
            </script>
          </material>
        </visual>
        <gravity>1</gravity>
        <velocity_decay/>
        <self_collide>0</self_collide>
        <kinematic>0</kinematic>
      </link>
      <joint name='thruster_4_joint' type='revolute'>
        <child>thruster_4</child>
        <parent>base_link</parent>
        <axis>
          <xyz>1 0 0</xyz>
          <limit>
            <lower>-1e+16</lower>
            <upper>1e+16</upper>
          </limit>
          <dynamics>
            <spring_reference>0</spring_reference>
            <spring_stiffness>0</spring_stiffness>
          </dynamics>
          <use_parent_model_frame>1</use_parent_model_frame>
        </axis>
      </joint>
      <link name='thruster_5'>
        <pose frame=''>0 -0.4 0 0 -0 0</pose>
        <inertial>
          <pose frame=''>0 0 0 0 -0 0</pose>
          <mass>0.001</mass>
          <inertia>
            <ixx>1.7e-08</ixx>
            <ixy>0</ixy>
            <ixz>0</ixz>
            <iyy>1.7e-08</iyy>
            <iyz>0</iyz>
            <izz>1.7e-08</izz>
          </inertia>
        </inertial>
        <visual name='thruster_5_visual'>
          <pose frame=''>0.025 0 0 0 -0 0</pose>
          <geometry>
            <box>
              <size>0.01 0.01 0.1</size>
            </box>
          </geometry>
          <material>
            <script>
              <uri>__default__</uri>
              <name>__default__</name>
            </script>
          </material>
        </visual>
        <visual name='thruster_5_visual_1'>
          <pose frame=''>0 0 0 3.14159 1.57079 3.14159</pose>
          <geometry>
            <cylinder>
              <length>0.05</length>
              <radius>0.01</radius>
            </cylinder>
          </geometry>
          <material>
            <script>
              <uri>__default__</uri>
              <name>__default__</name>
            </script>
          </material>
        </visual>
        <gravity>1</gravity>
        <velocity_decay/>
        <self_collide>0</self_collide>
        <kinematic>0</kinematic>
      </link>
      <joint name='thruster_5_joint' type='revolute'>
        <child>thruster_5</child>
        <parent>base_link</parent>
        <axis>
          <xyz>1 0 0</xyz>
          <limit>
            <lower>-1e+16</lower>
            <upper>1e+16</upper>
          </limit>
          <dynamics>
            <spring_reference>0</spring_reference>
            <spring_stiffness>0</spring_stiffness>
          </dynamics>
          <use_parent_model_frame>1</use_parent_model_frame>
        </axis>
      </joint>
      <link name='thruster_6'>
        <pose frame=''>0.4 0 0.2 0 0 -1.5708</pose>
        <inertial>
          <pose frame=''>0 0 0 0 -0 0</pose>
          <mass>0.001</mass>
          <inertia>
            <ixx>1.7e-08</ixx>
            <ixy>0</ixy>
            <ixz>0</ixz>
            <iyy>1.7e-08</iyy>
            <iyz>0</iyz>
            <izz>1.7e-08</izz>
          </inertia>
        </inertial>
        <visual name='thruster_6_visual'>
          <pose frame=''>0.025 0 0 0 -0 0</pose>
          <geometry>
            <box>
              <size>0.01 0.01 0.1</size>
            </box>
          </geometry>
          <material>
            <script>
              <uri>__default__</uri>
              <name>__default__</name>
            </script>
          </material>
        </visual>
        <visual name='thruster_6_visual_1'>
          <pose frame=''>0 0 0 3.14159 1.57079 3.14159</pose>
          <geometry>
            <cylinder>
              <length>0.05</length>
              <radius>0.01</radius>
            </cylinder>
          </geometry>
          <material>
            <script>
              <uri>__default__</uri>
              <name>__default__</name>
            </script>
          </material>
        </visual>
        <gravity>1</gravity>
        <velocity_decay/>
        <self_collide>0</self_collide>
        <kinematic>0</kinematic>
      </link>
      <joint name='thruster_6_joint' type='revolute'>
        <child>thruster_6</child>
        <parent>base_link</parent>
        <axis>
          <xyz>0 -1 0</xyz>
          <limit>
            <lower>-1e+16</lower>
            <upper>1e+16</upper>
          </limit>
          <dynamics>
            <spring_reference>0</spring_reference>
            <spring_stiffness>0</spring_stiffness>
          </dynamics>
          <use_parent_model_frame>1</use_parent_model_frame>
        </axis>
      </joint>
      <link name='thruster_7'>
        <pose frame=''>-0.4 0 0.2 0 0 -1.5708</pose>
        <inertial>
          <pose frame=''>0 0 0 0 -0 0</pose>
          <mass>0.001</mass>
          <inertia>
            <ixx>1.7e-08</ixx>
            <ixy>0</ixy>
            <ixz>0</ixz>
            <iyy>1.7e-08</iyy>
            <iyz>0</iyz>
            <izz>1.7e-08</izz>
          </inertia>
        </inertial>
        <visual name='thruster_7_visual'>
          <pose frame=''>0.025 0 0 0 -0 0</pose>
          <geometry>
            <box>
              <size>0.01 0.01 0.1</size>
            </box>
          </geometry>
          <material>
            <script>
              <uri>__default__</uri>
              <name>__default__</name>
            </script>
          </material>
        </visual>
        <visual name='thruster_7_visual_1'>
          <pose frame=''>0 0 0 3.14159 1.57079 3.14159</pose>
          <geometry>
            <cylinder>
              <length>0.05</length>
              <radius>0.01</radius>
            </cylinder>
          </geometry>
          <material>
            <script>
              <uri>__default__</uri>
              <name>__default__</name>
            </script>
          </material>
        </visual>
        <gravity>1</gravity>
        <velocity_decay/>
        <self_collide>0</self_collide>
        <kinematic>0</kinematic>
      </link>
      <joint name='thruster_7_joint' type='revolute'>
        <child>thruster_7</child>
        <parent>base_link</parent>
        <axis>
          <xyz>0 -1 0</xyz>
          <limit>
            <lower>-1e+16</lower>
            <upper>1e+16</upper>
          </limit>
          <dynamics>
            <spring_reference>0</spring_reference>
            <spring_stiffness>0</spring_stiffness>
          </dynamics>
          <use_parent_model_frame>1</use_parent_model_frame>
        </axis>
      </joint>
      <plugin name='uuv_plugin' filename='libuuv_underwater_object_plugin.so'>
        <fluid_density>1028</fluid_density>
        <flow_velocity_topic>hydrodynamics/current_velocity</flow_velocity_topic>
        <debug>0</debug>
        <link name='base_link'>
          <neutrally_buoyant>0</neutrally_buoyant>
          <center_of_buoyancy>0 0 0</center_of_buoyancy>
          <volume>0.05602053312</volume>
          <box>
            <width>0.3048</width>
            <length>0.9144</length>
            <height>0.2</height>
          </box>
          <hydrodynamic_model>
            <type>fossen</type>
            <added_mass>0 0 0 0 0 0 0 0 0 0 0 0 0 0 0 0 0 0 0 0 0 0 0 0 0 0 0 0 0 0 0 0 0 0 0 0</added_mass>
            <linear_damping>-3 -3 -3 -1 -1 -1</linear_damping>
            <linear_damping_forward_speed>0 0 0 0 0 0</linear_damping_forward_speed>
            <quadratic_damping>-1 -1 -1 -1 -1 -1</quadratic_damping>
          </hydrodynamic_model>
        </link>
        <robotNamespace>/</robotNamespace>
      </plugin>
      <plugin name='libuuv_gazebo_subseapressure_plugin' filename='libuuv_gazebo_ros_subsea_pressure_plugin.so'>
        <robot_namespace>aquadrone/out/</robot_namespace>
        <link_name>aquadrone/out//pressure_link</link_name>
        <sensor_topic>pressure</sensor_topic>
        <update_rate>10</update_rate>
        <saturation>30000</saturation>
        <noise_sigma>3.0</noise_sigma>
        <noise_amplitude>0.0</noise_amplitude>
        <estimate_depth_on>false</estimate_depth_on>
        <standard_pressure>101.325</standard_pressure>
        <kPa_per_meter>9.80638</kPa_per_meter>
        <enable_gazebo_messages>false</enable_gazebo_messages>
        <robotNamespace>/</robotNamespace>
      </plugin>
      <plugin name='libuuv_gazebo_imu_plugin' filename='libuuv_gazebo_ros_imu_plugin.so'>
        <robot_namespace>aquadrone/out/</robot_namespace>
        <link_name>aquadrone/out//imu_link</link_name>
        <sensor_topic>imu</sensor_topic>
        <gyroscope_noise_density>0.0003394</gyroscope_noise_density>
        <gyroscope_random_walk>3.8785e-05</gyroscope_random_walk>
        <gyroscope_bias_correlation_time>1000.0</gyroscope_bias_correlation_time>
        <gyroscope_turn_on_bias_sigma>0.0087</gyroscope_turn_on_bias_sigma>
        <accelerometer_noise_density>0.004</accelerometer_noise_density>
        <accelerometer_random_walk>0.006</accelerometer_random_walk>
        <accelerometer_bias_correlation_time>300.0</accelerometer_bias_correlation_time>
        <accelerometer_turn_on_bias_sigma>0.196</accelerometer_turn_on_bias_sigma>
        <orientation_noise>0.01</orientation_noise>
        <update_rate>50</update_rate>
        <enable_gazebo_messages>false</enable_gazebo_messages>
        <enable_local_ned_frame>false</enable_local_ned_frame>
        <static_reference_frame>world</static_reference_frame>
        <robotNamespace>/</robotNamespace>
      </plugin>
      <plugin name='0_thruster_model' filename='libuuv_thruster_ros_plugin.so'>
        <thrusterID>0</thrusterID>
        <linkName>thruster_0</linkName>
        <jointName>thruster_0_joint</jointName>
        <thrustTopic>thrusters/0/thrust</thrustTopic>
        <inputTopic>thrusters/0/input</inputTopic>
        <gain>1</gain>
        <clampMax>10</clampMax>
        <clampMin>-10</clampMin>
        <thrust_efficiency>1</thrust_efficiency>
        <propeller_efficiency>1</propeller_efficiency>
        <dynamics>
          <type>ZeroOrder</type>
        </dynamics>
        <conversion>
          <type>Basic</type>
          <rotorConstant>1</rotorConstant>
        </conversion>
        <robotNamespace>/</robotNamespace>
      </plugin>
      <plugin name='1_thruster_model' filename='libuuv_thruster_ros_plugin.so'>
        <thrusterID>1</thrusterID>
        <linkName>thruster_1</linkName>
        <jointName>thruster_1_joint</jointName>
        <thrustTopic>thrusters/1/thrust</thrustTopic>
        <inputTopic>thrusters/1/input</inputTopic>
        <gain>1</gain>
        <clampMax>10</clampMax>
        <clampMin>-10</clampMin>
        <thrust_efficiency>1</thrust_efficiency>
        <propeller_efficiency>1</propeller_efficiency>
        <dynamics>
          <type>ZeroOrder</type>
        </dynamics>
        <conversion>
          <type>Basic</type>
          <rotorConstant>1</rotorConstant>
        </conversion>
        <robotNamespace>/</robotNamespace>
      </plugin>
      <plugin name='2_thruster_model' filename='libuuv_thruster_ros_plugin.so'>
        <thrusterID>2</thrusterID>
        <linkName>thruster_2</linkName>
        <jointName>thruster_2_joint</jointName>
        <thrustTopic>thrusters/2/thrust</thrustTopic>
        <inputTopic>thrusters/2/input</inputTopic>
        <gain>1</gain>
        <clampMax>10</clampMax>
        <clampMin>-10</clampMin>
        <thrust_efficiency>1</thrust_efficiency>
        <propeller_efficiency>1</propeller_efficiency>
        <dynamics>
          <type>ZeroOrder</type>
        </dynamics>
        <conversion>
          <type>Basic</type>
          <rotorConstant>1</rotorConstant>
        </conversion>
        <robotNamespace>/</robotNamespace>
      </plugin>
      <plugin name='3_thruster_model' filename='libuuv_thruster_ros_plugin.so'>
        <thrusterID>3</thrusterID>
        <linkName>thruster_3</linkName>
        <jointName>thruster_3_joint</jointName>
        <thrustTopic>thrusters/3/thrust</thrustTopic>
        <inputTopic>thrusters/3/input</inputTopic>
        <gain>1</gain>
        <clampMax>10</clampMax>
        <clampMin>-10</clampMin>
        <thrust_efficiency>1</thrust_efficiency>
        <propeller_efficiency>1</propeller_efficiency>
        <dynamics>
          <type>ZeroOrder</type>
        </dynamics>
        <conversion>
          <type>Basic</type>
          <rotorConstant>1</rotorConstant>
        </conversion>
        <robotNamespace>/</robotNamespace>
      </plugin>
      <plugin name='4_thruster_model' filename='libuuv_thruster_ros_plugin.so'>
        <thrusterID>4</thrusterID>
        <linkName>thruster_4</linkName>
        <jointName>thruster_4_joint</jointName>
        <thrustTopic>thrusters/4/thrust</thrustTopic>
        <inputTopic>thrusters/4/input</inputTopic>
        <gain>1</gain>
        <clampMax>10</clampMax>
        <clampMin>-10</clampMin>
        <thrust_efficiency>1</thrust_efficiency>
        <propeller_efficiency>1</propeller_efficiency>
        <dynamics>
          <type>ZeroOrder</type>
        </dynamics>
        <conversion>
          <type>Basic</type>
          <rotorConstant>1</rotorConstant>
        </conversion>
        <robotNamespace>/</robotNamespace>
      </plugin>
      <plugin name='5_thruster_model' filename='libuuv_thruster_ros_plugin.so'>
        <thrusterID>5</thrusterID>
        <linkName>thruster_5</linkName>
        <jointName>thruster_5_joint</jointName>
        <thrustTopic>thrusters/5/thrust</thrustTopic>
        <inputTopic>thrusters/5/input</inputTopic>
        <gain>1</gain>
        <clampMax>10</clampMax>
        <clampMin>-10</clampMin>
        <thrust_efficiency>1</thrust_efficiency>
        <propeller_efficiency>1</propeller_efficiency>
        <dynamics>
          <type>ZeroOrder</type>
        </dynamics>
        <conversion>
          <type>Basic</type>
          <rotorConstant>1</rotorConstant>
        </conversion>
        <robotNamespace>/</robotNamespace>
      </plugin>
      <plugin name='6_thruster_model' filename='libuuv_thruster_ros_plugin.so'>
        <thrusterID>6</thrusterID>
        <linkName>thruster_6</linkName>
        <jointName>thruster_6_joint</jointName>
        <thrustTopic>thrusters/6/thrust</thrustTopic>
        <inputTopic>thrusters/6/input</inputTopic>
        <gain>1</gain>
        <clampMax>10</clampMax>
        <clampMin>-10</clampMin>
        <thrust_efficiency>1</thrust_efficiency>
        <propeller_efficiency>1</propeller_efficiency>
        <dynamics>
          <type>ZeroOrder</type>
        </dynamics>
        <conversion>
          <type>Basic</type>
          <rotorConstant>1</rotorConstant>
        </conversion>
        <robotNamespace>/</robotNamespace>
      </plugin>
      <static>0</static>
      <plugin name='7_thruster_model' filename='libuuv_thruster_ros_plugin.so'>
        <thrusterID>7</thrusterID>
        <linkName>thruster_7</linkName>
        <jointName>thruster_7_joint</jointName>
        <thrustTopic>thrusters/7/thrust</thrustTopic>
        <inputTopic>thrusters/7/input</inputTopic>
        <gain>1</gain>
        <clampMax>10</clampMax>
        <clampMin>-10</clampMin>
        <thrust_efficiency>1</thrust_efficiency>
        <propeller_efficiency>1</propeller_efficiency>
        <dynamics>
          <type>ZeroOrder</type>
        </dynamics>
        <conversion>
          <type>Basic</type>
          <rotorConstant>1</rotorConstant>
        </conversion>
        <robotNamespace>/</robotNamespace>
      </plugin>
      <pose frame=''>0 0 -5 0 -0 0</pose>
    </model>
    <model name='white_pole'>
      <link name='pole'>
        <pose frame=''>0 0 0 0 -0 0</pose>
        <inertial>
          <pose frame=''>2 0 0 0 -0 0</pose>
          <mass>1</mass>
          <inertia>
            <ixx>1</ixx>
            <ixy>0</ixy>
            <ixz>0</ixz>
            <iyy>100</iyy>
            <iyz>0</iyz>
            <izz>1</izz>
          </inertia>
        </inertial>
        <collision name='pole_collision'>
          <pose frame=''>0 0 0 0 -0 0</pose>
          <geometry>
            <cylinder>
              <length>10</length>
              <radius>0.1</radius>
            </cylinder>
          </geometry>
          <surface>
            <contact>
              <ode/>
            </contact>
            <friction>
              <ode/>
              <torsional>
                <ode/>
              </torsional>
            </friction>
            <bounce/>
          </surface>
          <max_contacts>10</max_contacts>
        </collision>
        <visual name='pole_visual'>
          <pose frame=''>0 0 0 0 -0 0</pose>
          <geometry>
            <cylinder>
              <length>10</length>
              <radius>0.1</radius>
            </cylinder>
          </geometry>
          <material>
            <script>
              <name>Gazebo/White</name>
              <uri>file://media/materials/scripts/gazebo.material</uri>
            </script>
          </material>
        </visual>
        <gravity>1</gravity>
        <velocity_decay/>
        <self_collide>0</self_collide>
        <kinematic>0</kinematic>
      </link>
      <static>1</static>
      <pose frame=''>0 -3 0 0 -0 0</pose>
    </model>
    <model name='red_pole'>
      <link name='pole'>
        <pose frame=''>0 0 0 0 -0 0</pose>
        <inertial>
          <pose frame=''>2 0 0 0 -0 0</pose>
          <mass>1</mass>
          <inertia>
            <ixx>1</ixx>
            <ixy>0</ixy>
            <ixz>0</ixz>
            <iyy>100</iyy>
            <iyz>0</iyz>
            <izz>1</izz>
          </inertia>
        </inertial>
        <collision name='pole_collision'>
          <pose frame=''>0 0 0 0 -0 0</pose>
          <geometry>
            <cylinder>
              <length>10</length>
              <radius>0.1</radius>
            </cylinder>
          </geometry>
          <surface>
            <contact>
              <ode/>
            </contact>
            <friction>
              <ode/>
              <torsional>
                <ode/>
              </torsional>
            </friction>
            <bounce/>
          </surface>
          <max_contacts>10</max_contacts>
        </collision>
        <visual name='pole_visual'>
          <pose frame=''>0 0 0 0 -0 0</pose>
          <geometry>
            <cylinder>
              <length>10</length>
              <radius>0.1</radius>
            </cylinder>
          </geometry>
          <material>
            <script>
              <name>Gazebo/Red</name>
              <uri>file://media/materials/scripts/gazebo.material</uri>
            </script>
          </material>
        </visual>
        <gravity>1</gravity>
        <velocity_decay/>
        <self_collide>0</self_collide>
        <kinematic>0</kinematic>
      </link>
      <static>1</static>
      <pose frame=''>3 0 0 0 -0 0</pose>
    </model>
    <model name='green_pole'>
      <link name='pole'>
        <pose frame=''>0 0 0 0 -0 0</pose>
        <inertial>
          <pose frame=''>2 0 0 0 -0 0</pose>
          <mass>1</mass>
          <inertia>
            <ixx>1</ixx>
            <ixy>0</ixy>
            <ixz>0</ixz>
            <iyy>100</iyy>
            <iyz>0</iyz>
            <izz>1</izz>
          </inertia>
        </inertial>
        <collision name='pole_collision'>
          <pose frame=''>0 0 0 0 -0 0</pose>
          <geometry>
            <cylinder>
              <length>10</length>
              <radius>0.1</radius>
            </cylinder>
          </geometry>
          <surface>
            <contact>
              <ode/>
            </contact>
            <friction>
              <ode/>
              <torsional>
                <ode/>
              </torsional>
            </friction>
            <bounce/>
          </surface>
          <max_contacts>10</max_contacts>
        </collision>
        <visual name='pole_visual'>
          <pose frame=''>0 0 0 0 -0 0</pose>
          <geometry>
            <cylinder>
              <length>10</length>
              <radius>0.1</radius>
            </cylinder>
          </geometry>
          <material>
            <script>
              <name>Gazebo/Green</name>
              <uri>file://media/materials/scripts/gazebo.material</uri>
            </script>
          </material>
        </visual>
        <gravity>1</gravity>
        <velocity_decay/>
        <self_collide>0</self_collide>
        <kinematic>0</kinematic>
      </link>
      <static>1</static>
      <pose frame=''>0 3 0 0 -0 0</pose>
    </model>
    <model name='blue_pole'>
      <link name='pole'>
        <pose frame=''>0 0 0 0 -0 0</pose>
        <inertial>
          <pose frame=''>2 0 0 0 -0 0</pose>
          <mass>1</mass>
          <inertia>
            <ixx>1</ixx>
            <ixy>0</ixy>
            <ixz>0</ixz>
            <iyy>100</iyy>
            <iyz>0</iyz>
            <izz>1</izz>
          </inertia>
        </inertial>
        <collision name='pole_collision'>
          <pose frame=''>0 0 0 0 -0 0</pose>
          <geometry>
            <cylinder>
              <length>10</length>
              <radius>0.1</radius>
            </cylinder>
          </geometry>
          <surface>
            <contact>
              <ode/>
            </contact>
            <friction>
              <ode/>
              <torsional>
                <ode/>
              </torsional>
            </friction>
            <bounce/>
          </surface>
          <max_contacts>10</max_contacts>
        </collision>
        <visual name='pole_visual'>
          <pose frame=''>0 0 0 0 -0 0</pose>
          <geometry>
            <cylinder>
              <length>10</length>
              <radius>0.1</radius>
            </cylinder>
          </geometry>
          <material>
            <script>
              <name>Gazebo/Blue</name>
              <uri>file://media/materials/scripts/gazebo.material</uri>
            </script>
          </material>
        </visual>
        <gravity>1</gravity>
        <velocity_decay/>
        <self_collide>0</self_collide>
        <kinematic>0</kinematic>
      </link>
      <static>1</static>
      <pose frame=''>-3 0 0 0 -0 0</pose>
    </model>
    <state world_name='empty_underwater'>
      <sim_time>438 680000000</sim_time>
      <real_time>453 301448577</real_time>
      <wall_time>1578786044 172958882</wall_time>
      <iterations>219340</iterations>
      <model name='aquadrone'>
        <pose frame=''>-0.24396 0.003479 -2.71895 0.001417 -0.018427 1.65394</pose>
        <scale>1 1 1</scale>
        <link name='aquadrone/out//imu_link'>
          <pose frame=''>-0.24396 0.003479 -2.71895 0.001417 -0.018427 1.65394</pose>
          <velocity>0.005105 0.010069 -0.000165 -6.1e-05 -7.9e-05 0.033212</velocity>
          <acceleration>-0.000392 0.000243 3.9e-05 6e-05 -0.000461 0.025265</acceleration>
          <wrench>-6e-06 4e-06 1e-06 0 -0 0</wrench>
        </link>
        <link name='aquadrone/out//pressure_link'>
          <pose frame=''>-0.24396 0.003479 -2.71895 0.001417 -0.018427 1.65394</pose>
          <velocity>0.005105 0.010069 -0.000165 -6.1e-05 -7.9e-05 0.033212</velocity>
          <acceleration>-0.000392 0.000243 3.9e-05 6e-05 -0.000461 0.025265</acceleration>
          <wrench>-6e-06 4e-06 1e-06 0 -0 0</wrench>
        </link>
        <link name='base_link'>
          <pose frame=''>-0.24396 0.003479 -2.71895 0.001417 -0.018427 1.65394</pose>
          <velocity>0.005105 0.010069 -0.000165 -6.1e-05 -7.9e-05 0.033212</velocity>
          <acceleration>-0.000392 0.000243 3.9e-05 0.000257 -0.001567 0.027246</acceleration>
          <wrench>-0.022459 0.013921 0.002217 0 -0 0</wrench>
        </link>
        <link name='thruster_0'>
          <pose frame=''>-0.676379 0.372449 -2.91098 2.6426 1.55231 1.73085</pose>
          <velocity>-0.007135 -0.004304 -0.000222 -0.002354 0.014147 -0.746383</velocity>
          <acceleration>-0.009391 -0.01087 -0.000138 -0.00022 -6.1e-05 -0</acceleration>
          <wrench>-9e-06 -1.1e-05 0 0 -0 0</wrench>
        </link>
        <link name='thruster_1'>
          <pose frame=''>0.120855 0.438907 -2.91211 3.13233 1.55231 1.73069</pose>
          <velocity>-0.009341 0.022174 -0.000163 -0.002355 0.014152 -0.746639</velocity>
          <acceleration>-0.011501 0.009236 0.000232 -0.00022 -6.1e-05 -0</acceleration>
          <wrench>-1.2e-05 9e-06 0 0 -0 0</wrench>
        </link>
        <link name='thruster_2'>
          <pose frame=''>-0.609953 -0.424652 -2.92572 2.12801 1.55231 1.73098</pose>
          <velocity>0.01934 -0.002099 -0.000168 -0.002347 0.0141 -0.743776</velocity>
          <acceleration>0.010719 -0.008759 -0.000155 -0.000219 -6.1e-05 0</acceleration>
          <wrench>1.1e-05 -9e-06 0 0 -0 0</wrench>
        </link>
        <link name='thruster_3'>
          <pose frame=''>0.187281 -0.358194 -2.92685 2.61675 1.55231 1.73086</pose>
          <velocity>0.017133 0.024378 -0.000109 -0.002347 0.014104 -0.744033</velocity>
          <acceleration>0.008608 0.011347 0.000216 -0.000219 -6.1e-05 0</acceleration>
          <wrench>9e-06 1.1e-05 0 0 -0 0</wrench>
        </link>
        <link name='thruster_4'>
          <pose frame=''>-0.642577 -0.029751 -2.71838 0.218654 -0.018427 1.65394</pose>
          <velocity>0.006208 -0.00317 -0.000195 0.007102 -0.086066 0.031622</velocity>
          <acceleration>0.000663 -0.00981 -0.000147 0.001477 -0.000344 0.025268</acceleration>
          <wrench>1e-06 -1e-05 0 0 -0 0</wrench>
        </link>
        <link name='thruster_5'>
          <pose frame=''>0.154657 0.036708 -2.71952 -0.216161 -0.018427 1.65394</pose>
          <velocity>0.004002 0.023308 -0.000136 -0.007223 0.085908 0.034802</velocity>
          <acceleration>-0.001447 0.010296 0.000224 -0.001357 -0.00058 0.025262</acceleration>
          <wrench>-1e-06 1e-05 0 0 -0 0</wrench>
        </link>
        <link name='thruster_6'>
          <pose frame=''>-0.276585 0.39838 -2.51161 0.669467 0.001419 0.083166</pose>
          <velocity>-0.008027 0.008998 -0.000192 -0.258064 -0.021577 0.033579</velocity>
          <acceleration>-0.010447 -0.000808 4.7e-05 0.000428 -0.004711 0.025256</acceleration>
          <wrench>-1e-05 -1e-06 0 0 -0 0</wrench>
        </link>
        <link name='thruster_7'>
          <pose frame=''>-0.210159 -0.398721 -2.52635 -0.633396 0.001414 0.083166</pose>
          <velocity>0.018447 0.011203 -0.000138 0.257943 0.02142 0.032845</velocity>
          <acceleration>0.009663 0.001303 3.1e-05 -0.00028 0.003792 0.025274</acceleration>
          <wrench>1e-05 1e-06 0 0 -0 0</wrench>
        </link>
      </model>
      <model name='blue_pole'>
        <pose frame=''>-3 0 0 0 -0 0</pose>
        <scale>1 1 1</scale>
        <link name='pole'>
          <pose frame=''>-3 0 0 0 -0 0</pose>
          <velocity>0 0 0 0 -0 0</velocity>
          <acceleration>0 0 0 0 -0 0</acceleration>
          <wrench>0 0 0 0 -0 0</wrench>
        </link>
      </model>
      <model name='green_pole'>
        <pose frame=''>0 3 0 0 -0 0</pose>
        <scale>1 1 1</scale>
        <link name='pole'>
          <pose frame=''>0 3 0 0 -0 0</pose>
          <velocity>0 0 0 0 -0 0</velocity>
          <acceleration>0 0 0 0 -0 0</acceleration>
          <wrench>0 0 0 0 -0 0</wrench>
        </link>
      </model>
      <model name='ocean_box'>
        <pose frame=''>0 0 0 0 -0 0</pose>
        <scale>1 1 1</scale>
        <link name='link'>
          <pose frame=''>0 0 0 0 -0 0</pose>
          <velocity>0 0 0 0 -0 0</velocity>
          <acceleration>0 0 0 0 -0 0</acceleration>
          <wrench>0 0 0 0 -0 0</wrench>
        </link>
      </model>
      <model name='red_pole'>
        <pose frame=''>3 0 0 0 -0 0</pose>
        <scale>1 1 1</scale>
        <link name='pole'>
          <pose frame=''>3 0 0 0 -0 0</pose>
          <velocity>0 0 0 0 -0 0</velocity>
          <acceleration>0 0 0 0 -0 0</acceleration>
          <wrench>0 0 0 0 -0 0</wrench>
        </link>
      </model>
      <model name='white_pole'>
        <pose frame=''>0 -3 0 0 -0 0</pose>
        <scale>1 1 1</scale>
        <link name='pole'>
          <pose frame=''>0 -3 0 0 -0 0</pose>
          <velocity>0 0 0 0 -0 0</velocity>
          <acceleration>0 0 0 0 -0 0</acceleration>
          <wrench>0 0 0 0 -0 0</wrench>
        </link>
      </model>
      <light name='sun'>
        <pose frame=''>0 0 10 0 -0 0</pose>
      </light>
    </state>
    <gui fullscreen='0'>
      <camera name='user_camera'>
        <pose frame=''>5.62552 -6.07651 2.312 0 0.275643 2.35619</pose>
        <view_controller>orbit</view_controller>
        <projection_type>perspective</projection_type>
      </camera>
    </gui>
  </world>
</sdf>
